[2024-05-27T22:12:13.709+0000] {taskinstance.py:1087} INFO - Dependencies all met for <TaskInstance: franko_lookup_ingest.ti_load_stage_data manual__2024-05-27T21:49:08.726117+00:00 [queued]>
[2024-05-27T22:12:13.726+0000] {taskinstance.py:1087} INFO - Dependencies all met for <TaskInstance: franko_lookup_ingest.ti_load_stage_data manual__2024-05-27T21:49:08.726117+00:00 [queued]>
[2024-05-27T22:12:13.726+0000] {taskinstance.py:1283} INFO - 
--------------------------------------------------------------------------------
[2024-05-27T22:12:13.727+0000] {taskinstance.py:1284} INFO - Starting attempt 6 of 6
[2024-05-27T22:12:13.727+0000] {taskinstance.py:1285} INFO - 
--------------------------------------------------------------------------------
[2024-05-27T22:12:13.751+0000] {taskinstance.py:1304} INFO - Executing <Task(DockerOperator): ti_load_stage_data> on 2024-05-27 21:49:08.726117+00:00
[2024-05-27T22:12:13.759+0000] {standard_task_runner.py:55} INFO - Started process 10864 to run task
[2024-05-27T22:12:13.764+0000] {standard_task_runner.py:82} INFO - Running: ['***', 'tasks', 'run', 'franko_lookup_ingest', 'ti_load_stage_data', 'manual__2024-05-27T21:49:08.726117+00:00', '--job-id', '92', '--raw', '--subdir', 'DAGS_FOLDER/challenge_dag.py', '--cfg-path', '/tmp/tmp5sqkw5r5']
[2024-05-27T22:12:13.765+0000] {standard_task_runner.py:83} INFO - Job 92: Subtask ti_load_stage_data
[2024-05-27T22:12:13.842+0000] {task_command.py:389} INFO - Running <TaskInstance: franko_lookup_ingest.ti_load_stage_data manual__2024-05-27T21:49:08.726117+00:00 [running]> on host a64b6410e10e
[2024-05-27T22:12:13.930+0000] {taskinstance.py:1513} INFO - Exporting the following env vars:
AIRFLOW_CTX_DAG_OWNER=***
AIRFLOW_CTX_DAG_ID=franko_lookup_ingest
AIRFLOW_CTX_TASK_ID=ti_load_stage_data
AIRFLOW_CTX_EXECUTION_DATE=2024-05-27T21:49:08.726117+00:00
AIRFLOW_CTX_TRY_NUMBER=6
AIRFLOW_CTX_DAG_RUN_ID=manual__2024-05-27T21:49:08.726117+00:00
[2024-05-27T22:12:13.953+0000] {docker.py:284} INFO - Starting docker container from image my_dbt
[2024-05-27T22:12:16.277+0000] {docker.py:354} INFO - [0m22:12:16  Running with dbt=1.5.11
[2024-05-27T22:12:16.424+0000] {docker.py:354} INFO - [0m22:12:16  Registered adapter: postgres=1.5.11
[2024-05-27T22:12:16.530+0000] {docker.py:354} INFO - [0m22:12:16  Found 3 models, 4 tests, 0 snapshots, 0 analyses, 310 macros, 0 operations, 1 seed file, 1 source, 0 exposures, 0 metrics, 0 groups
[2024-05-27T22:12:16.531+0000] {docker.py:354} INFO - [0m22:12:16
[2024-05-27T22:12:16.604+0000] {docker.py:354} INFO - [0m22:12:16  Concurrency: 4 threads (target='dev')
[2024-05-27T22:12:16.604+0000] {docker.py:354} INFO - [0m22:12:16
[2024-05-27T22:12:16.607+0000] {docker.py:354} INFO - [0m22:12:16  1 of 1 START sql table model dev.silver_covid_geo .............................. [RUN]
[2024-05-27T22:12:16.713+0000] {docker.py:354} INFO - [0m22:12:16  1 of 1 ERROR creating sql table model dev.silver_covid_geo ..................... [[31mERROR[0m in 0.10s]
[2024-05-27T22:12:16.817+0000] {docker.py:354} INFO - [0m22:12:16
[2024-05-27T22:12:16.817+0000] {docker.py:354} INFO - [0m22:12:16  Finished running 1 table model in 0 hours 0 minutes and 0.28 seconds (0.28s).
[2024-05-27T22:12:16.825+0000] {docker.py:354} INFO - [0m22:12:16
[2024-05-27T22:12:16.825+0000] {docker.py:354} INFO - [0m22:12:16  [31mCompleted with 1 error and 0 warnings:[0m
[2024-05-27T22:12:16.826+0000] {docker.py:354} INFO - [0m22:12:16
[2024-05-27T22:12:16.826+0000] {docker.py:354} INFO - [0m22:12:16  [33mDatabase Error in model silver_covid_geo (models/silver/silver_covid_geo.sql)[0m
[2024-05-27T22:12:16.826+0000] {docker.py:354} INFO - [0m22:12:16    syntax error at or near "1"
[2024-05-27T22:12:16.827+0000] {docker.py:354} INFO - [0m22:12:16    LINE 22: "1/22/20"         as 1_22_20,
[2024-05-27T22:12:16.827+0000] {docker.py:354} INFO - [0m22:12:16                                  ^
[2024-05-27T22:12:16.827+0000] {docker.py:354} INFO - [0m22:12:16    compiled Code at target/run/franko/models/silver/silver_covid_geo.sql
[2024-05-27T22:12:16.828+0000] {docker.py:354} INFO - [0m22:12:16
[2024-05-27T22:12:16.828+0000] {docker.py:354} INFO - [0m22:12:16  Done. PASS=0 WARN=0 ERROR=1 SKIP=0 TOTAL=1
[2024-05-27T22:12:17.825+0000] {taskinstance.py:1772} ERROR - Task failed with exception
Traceback (most recent call last):
  File "/home/airflow/.local/lib/python3.7/site-packages/airflow/providers/docker/operators/docker.py", line 430, in execute
    return self._run_image()
  File "/home/airflow/.local/lib/python3.7/site-packages/airflow/providers/docker/operators/docker.py", line 303, in _run_image
    return self._run_image_with_mounts(self.mounts, add_tmp_variable=False)
  File "/home/airflow/.local/lib/python3.7/site-packages/airflow/providers/docker/operators/docker.py", line 359, in _run_image_with_mounts
    raise AirflowException(f"Docker container failed: {repr(result)} lines {joined_log_lines}")
airflow.exceptions.AirflowException: Docker container failed: {'StatusCode': 1} lines [0m22:12:16  Running with dbt=1.5.11
[0m22:12:16  Registered adapter: postgres=1.5.11
[0m22:12:16  Found 3 models, 4 tests, 0 snapshots, 0 analyses, 310 macros, 0 operations, 1 seed file, 1 source, 0 exposures, 0 metrics, 0 groups
[0m22:12:16
[0m22:12:16  Concurrency: 4 threads (target='dev')
[0m22:12:16
[0m22:12:16  1 of 1 START sql table model dev.silver_covid_geo .............................. [RUN]
[0m22:12:16  1 of 1 ERROR creating sql table model dev.silver_covid_geo ..................... [[31mERROR[0m in 0.10s]
[0m22:12:16
[0m22:12:16  Finished running 1 table model in 0 hours 0 minutes and 0.28 seconds (0.28s).
[0m22:12:16
[0m22:12:16  [31mCompleted with 1 error and 0 warnings:[0m
[0m22:12:16
[0m22:12:16  [33mDatabase Error in model silver_covid_geo (models/silver/silver_covid_geo.sql)[0m
[0m22:12:16    syntax error at or near "1"
[0m22:12:16    LINE 22: "1/22/20"         as 1_22_20,
[0m22:12:16                                  ^
[0m22:12:16    compiled Code at target/run/franko/models/silver/silver_covid_geo.sql
[0m22:12:16
[0m22:12:16  Done. PASS=0 WARN=0 ERROR=1 SKIP=0 TOTAL=1
[2024-05-27T22:12:17.828+0000] {taskinstance.py:1327} INFO - Marking task as FAILED. dag_id=franko_lookup_ingest, task_id=ti_load_stage_data, execution_date=20240527T214908, start_date=20240527T221213, end_date=20240527T221217
[2024-05-27T22:12:17.841+0000] {standard_task_runner.py:105} ERROR - Failed to execute job 92 for task ti_load_stage_data (Docker container failed: {'StatusCode': 1} lines [0m22:12:16  Running with dbt=1.5.11
[0m22:12:16  Registered adapter: postgres=1.5.11
[0m22:12:16  Found 3 models, 4 tests, 0 snapshots, 0 analyses, 310 macros, 0 operations, 1 seed file, 1 source, 0 exposures, 0 metrics, 0 groups
[0m22:12:16
[0m22:12:16  Concurrency: 4 threads (target='dev')
[0m22:12:16
[0m22:12:16  1 of 1 START sql table model dev.silver_covid_geo .............................. [RUN]
[0m22:12:16  1 of 1 ERROR creating sql table model dev.silver_covid_geo ..................... [[31mERROR[0m in 0.10s]
[0m22:12:16
[0m22:12:16  Finished running 1 table model in 0 hours 0 minutes and 0.28 seconds (0.28s).
[0m22:12:16
[0m22:12:16  [31mCompleted with 1 error and 0 warnings:[0m
[0m22:12:16
[0m22:12:16  [33mDatabase Error in model silver_covid_geo (models/silver/silver_covid_geo.sql)[0m
[0m22:12:16    syntax error at or near "1"
[0m22:12:16    LINE 22: "1/22/20"         as 1_22_20,
[0m22:12:16                                  ^
[0m22:12:16    compiled Code at target/run/franko/models/silver/silver_covid_geo.sql
[0m22:12:16
[0m22:12:16  Done. PASS=0 WARN=0 ERROR=1 SKIP=0 TOTAL=1; 10864)
[2024-05-27T22:12:17.866+0000] {local_task_job.py:159} INFO - Task exited with return code 1
[2024-05-27T22:12:17.884+0000] {taskinstance.py:2582} INFO - 0 downstream tasks scheduled from follow-on schedule check
