[2024-05-27T22:31:15.245+0000] {taskinstance.py:1087} INFO - Dependencies all met for <TaskInstance: franko_lookup_ingest.ti_load_stage_data manual__2024-05-27T21:49:08.726117+00:00 [queued]>
[2024-05-27T22:31:15.259+0000] {taskinstance.py:1087} INFO - Dependencies all met for <TaskInstance: franko_lookup_ingest.ti_load_stage_data manual__2024-05-27T21:49:08.726117+00:00 [queued]>
[2024-05-27T22:31:15.259+0000] {taskinstance.py:1283} INFO - 
--------------------------------------------------------------------------------
[2024-05-27T22:31:15.259+0000] {taskinstance.py:1284} INFO - Starting attempt 12 of 12
[2024-05-27T22:31:15.260+0000] {taskinstance.py:1285} INFO - 
--------------------------------------------------------------------------------
[2024-05-27T22:31:15.280+0000] {taskinstance.py:1304} INFO - Executing <Task(DockerOperator): ti_load_stage_data> on 2024-05-27 21:49:08.726117+00:00
[2024-05-27T22:31:15.287+0000] {standard_task_runner.py:55} INFO - Started process 12332 to run task
[2024-05-27T22:31:15.291+0000] {standard_task_runner.py:82} INFO - Running: ['***', 'tasks', 'run', 'franko_lookup_ingest', 'ti_load_stage_data', 'manual__2024-05-27T21:49:08.726117+00:00', '--job-id', '98', '--raw', '--subdir', 'DAGS_FOLDER/challenge_dag.py', '--cfg-path', '/tmp/tmpw0k79c_q']
[2024-05-27T22:31:15.291+0000] {standard_task_runner.py:83} INFO - Job 98: Subtask ti_load_stage_data
[2024-05-27T22:31:15.372+0000] {task_command.py:389} INFO - Running <TaskInstance: franko_lookup_ingest.ti_load_stage_data manual__2024-05-27T21:49:08.726117+00:00 [running]> on host a64b6410e10e
[2024-05-27T22:31:15.473+0000] {taskinstance.py:1513} INFO - Exporting the following env vars:
AIRFLOW_CTX_DAG_OWNER=***
AIRFLOW_CTX_DAG_ID=franko_lookup_ingest
AIRFLOW_CTX_TASK_ID=ti_load_stage_data
AIRFLOW_CTX_EXECUTION_DATE=2024-05-27T21:49:08.726117+00:00
AIRFLOW_CTX_TRY_NUMBER=12
AIRFLOW_CTX_DAG_RUN_ID=manual__2024-05-27T21:49:08.726117+00:00
[2024-05-27T22:31:15.497+0000] {docker.py:284} INFO - Starting docker container from image my_dbt
[2024-05-27T22:31:17.836+0000] {docker.py:354} INFO - [0m22:31:17  Running with dbt=1.5.11
[2024-05-27T22:31:17.958+0000] {docker.py:354} INFO - [0m22:31:17  Registered adapter: postgres=1.5.11
[2024-05-27T22:31:18.055+0000] {docker.py:354} INFO - [0m22:31:18  Found 3 models, 4 tests, 0 snapshots, 0 analyses, 310 macros, 0 operations, 1 seed file, 1 source, 0 exposures, 0 metrics, 0 groups
[2024-05-27T22:31:18.056+0000] {docker.py:354} INFO - [0m22:31:18
[2024-05-27T22:31:18.123+0000] {docker.py:354} INFO - [0m22:31:18  Concurrency: 4 threads (target='dev')
[2024-05-27T22:31:18.123+0000] {docker.py:354} INFO - [0m22:31:18
[2024-05-27T22:31:18.126+0000] {docker.py:354} INFO - [0m22:31:18  1 of 1 START sql view model dev.silver_covid_geo ............................... [RUN]
[2024-05-27T22:31:18.207+0000] {docker.py:354} INFO - [0m22:31:18  1 of 1 ERROR creating sql view model dev.silver_covid_geo ...................... [[31mERROR[0m in 0.08s]
[2024-05-27T22:31:18.237+0000] {docker.py:354} INFO - [0m22:31:18
[2024-05-27T22:31:18.237+0000] {docker.py:354} INFO - [0m22:31:18  Finished running 1 view model in 0 hours 0 minutes and 0.18 seconds (0.18s).
[2024-05-27T22:31:18.250+0000] {docker.py:354} INFO - [0m22:31:18
[2024-05-27T22:31:18.251+0000] {docker.py:354} INFO - [0m22:31:18  [31mCompleted with 1 error and 0 warnings:[0m
[2024-05-27T22:31:18.251+0000] {docker.py:354} INFO - [0m22:31:18
[2024-05-27T22:31:18.252+0000] {docker.py:354} INFO - [0m22:31:18  [33mDatabase Error in model silver_covid_geo (models/silver/silver_covid_geo.sql)[0m
[2024-05-27T22:31:18.252+0000] {docker.py:354} INFO - [0m22:31:18    syntax error at or near "{"
[2024-05-27T22:31:18.253+0000] {docker.py:354} INFO - [0m22:31:18    LINE 7:     { {
[2024-05-27T22:31:18.253+0000] {docker.py:354} INFO - [0m22:31:18                ^
[2024-05-27T22:31:18.254+0000] {docker.py:354} INFO - [0m22:31:18    compiled Code at target/run/franko/models/silver/silver_covid_geo.sql
[2024-05-27T22:31:18.254+0000] {docker.py:354} INFO - [0m22:31:18
[2024-05-27T22:31:18.255+0000] {docker.py:354} INFO - [0m22:31:18  Done. PASS=0 WARN=0 ERROR=1 SKIP=0 TOTAL=1
[2024-05-27T22:31:19.215+0000] {taskinstance.py:1772} ERROR - Task failed with exception
Traceback (most recent call last):
  File "/home/airflow/.local/lib/python3.7/site-packages/airflow/providers/docker/operators/docker.py", line 430, in execute
    return self._run_image()
  File "/home/airflow/.local/lib/python3.7/site-packages/airflow/providers/docker/operators/docker.py", line 303, in _run_image
    return self._run_image_with_mounts(self.mounts, add_tmp_variable=False)
  File "/home/airflow/.local/lib/python3.7/site-packages/airflow/providers/docker/operators/docker.py", line 359, in _run_image_with_mounts
    raise AirflowException(f"Docker container failed: {repr(result)} lines {joined_log_lines}")
airflow.exceptions.AirflowException: Docker container failed: {'StatusCode': 1} lines [0m22:31:17  Running with dbt=1.5.11
[0m22:31:17  Registered adapter: postgres=1.5.11
[0m22:31:18  Found 3 models, 4 tests, 0 snapshots, 0 analyses, 310 macros, 0 operations, 1 seed file, 1 source, 0 exposures, 0 metrics, 0 groups
[0m22:31:18
[0m22:31:18  Concurrency: 4 threads (target='dev')
[0m22:31:18
[0m22:31:18  1 of 1 START sql view model dev.silver_covid_geo ............................... [RUN]
[0m22:31:18  1 of 1 ERROR creating sql view model dev.silver_covid_geo ...................... [[31mERROR[0m in 0.08s]
[0m22:31:18
[0m22:31:18  Finished running 1 view model in 0 hours 0 minutes and 0.18 seconds (0.18s).
[0m22:31:18
[0m22:31:18  [31mCompleted with 1 error and 0 warnings:[0m
[0m22:31:18
[0m22:31:18  [33mDatabase Error in model silver_covid_geo (models/silver/silver_covid_geo.sql)[0m
[0m22:31:18    syntax error at or near "{"
[0m22:31:18    LINE 7:     { {
[0m22:31:18                ^
[0m22:31:18    compiled Code at target/run/franko/models/silver/silver_covid_geo.sql
[0m22:31:18
[0m22:31:18  Done. PASS=0 WARN=0 ERROR=1 SKIP=0 TOTAL=1
[2024-05-27T22:31:19.218+0000] {taskinstance.py:1327} INFO - Marking task as FAILED. dag_id=franko_lookup_ingest, task_id=ti_load_stage_data, execution_date=20240527T214908, start_date=20240527T223115, end_date=20240527T223119
[2024-05-27T22:31:19.229+0000] {standard_task_runner.py:105} ERROR - Failed to execute job 98 for task ti_load_stage_data (Docker container failed: {'StatusCode': 1} lines [0m22:31:17  Running with dbt=1.5.11
[0m22:31:17  Registered adapter: postgres=1.5.11
[0m22:31:18  Found 3 models, 4 tests, 0 snapshots, 0 analyses, 310 macros, 0 operations, 1 seed file, 1 source, 0 exposures, 0 metrics, 0 groups
[0m22:31:18
[0m22:31:18  Concurrency: 4 threads (target='dev')
[0m22:31:18
[0m22:31:18  1 of 1 START sql view model dev.silver_covid_geo ............................... [RUN]
[0m22:31:18  1 of 1 ERROR creating sql view model dev.silver_covid_geo ...................... [[31mERROR[0m in 0.08s]
[0m22:31:18
[0m22:31:18  Finished running 1 view model in 0 hours 0 minutes and 0.18 seconds (0.18s).
[0m22:31:18
[0m22:31:18  [31mCompleted with 1 error and 0 warnings:[0m
[0m22:31:18
[0m22:31:18  [33mDatabase Error in model silver_covid_geo (models/silver/silver_covid_geo.sql)[0m
[0m22:31:18    syntax error at or near "{"
[0m22:31:18    LINE 7:     { {
[0m22:31:18                ^
[0m22:31:18    compiled Code at target/run/franko/models/silver/silver_covid_geo.sql
[0m22:31:18
[0m22:31:18  Done. PASS=0 WARN=0 ERROR=1 SKIP=0 TOTAL=1; 12332)
[2024-05-27T22:31:19.275+0000] {local_task_job.py:159} INFO - Task exited with return code 1
[2024-05-27T22:31:19.292+0000] {taskinstance.py:2582} INFO - 0 downstream tasks scheduled from follow-on schedule check
