[2024-05-28T02:17:44.184+0000] {taskinstance.py:1087} INFO - Dependencies all met for <TaskInstance: franko_lookup_ingest.ti_load_target_data manual__2024-05-27T21:49:08.726117+00:00 [queued]>
[2024-05-28T02:17:44.198+0000] {taskinstance.py:1087} INFO - Dependencies all met for <TaskInstance: franko_lookup_ingest.ti_load_target_data manual__2024-05-27T21:49:08.726117+00:00 [queued]>
[2024-05-28T02:17:44.199+0000] {taskinstance.py:1283} INFO - 
--------------------------------------------------------------------------------
[2024-05-28T02:17:44.199+0000] {taskinstance.py:1284} INFO - Starting attempt 18 of 18
[2024-05-28T02:17:44.199+0000] {taskinstance.py:1285} INFO - 
--------------------------------------------------------------------------------
[2024-05-28T02:17:44.216+0000] {taskinstance.py:1304} INFO - Executing <Task(DockerOperator): ti_load_target_data> on 2024-05-27 21:49:08.726117+00:00
[2024-05-28T02:17:44.221+0000] {standard_task_runner.py:55} INFO - Started process 6994 to run task
[2024-05-28T02:17:44.225+0000] {standard_task_runner.py:82} INFO - Running: ['***', 'tasks', 'run', 'franko_lookup_ingest', 'ti_load_target_data', 'manual__2024-05-27T21:49:08.726117+00:00', '--job-id', '195', '--raw', '--subdir', 'DAGS_FOLDER/challenge_dag.py', '--cfg-path', '/tmp/tmp9a7imu8u']
[2024-05-28T02:17:44.225+0000] {standard_task_runner.py:83} INFO - Job 195: Subtask ti_load_target_data
[2024-05-28T02:17:44.290+0000] {task_command.py:389} INFO - Running <TaskInstance: franko_lookup_ingest.ti_load_target_data manual__2024-05-27T21:49:08.726117+00:00 [running]> on host a64b6410e10e
[2024-05-28T02:17:44.378+0000] {taskinstance.py:1513} INFO - Exporting the following env vars:
AIRFLOW_CTX_DAG_OWNER=***
AIRFLOW_CTX_DAG_ID=franko_lookup_ingest
AIRFLOW_CTX_TASK_ID=ti_load_target_data
AIRFLOW_CTX_EXECUTION_DATE=2024-05-27T21:49:08.726117+00:00
AIRFLOW_CTX_TRY_NUMBER=18
AIRFLOW_CTX_DAG_RUN_ID=manual__2024-05-27T21:49:08.726117+00:00
[2024-05-28T02:17:44.401+0000] {docker.py:284} INFO - Starting docker container from image my_dbt
[2024-05-28T02:17:47.405+0000] {docker.py:354} INFO - [0m02:17:47  Running with dbt=1.5.11
[2024-05-28T02:17:47.554+0000] {docker.py:354} INFO - [0m02:17:47  Registered adapter: postgres=1.5.11
[2024-05-28T02:17:47.696+0000] {docker.py:354} INFO - [0m02:17:47  Found 6 models, 4 tests, 0 snapshots, 0 analyses, 422 macros, 0 operations, 1 seed file, 1 source, 0 exposures, 0 metrics, 0 groups
[2024-05-28T02:17:47.698+0000] {docker.py:354} INFO - [0m02:17:47
[2024-05-28T02:17:47.789+0000] {docker.py:354} INFO - [0m02:17:47  Concurrency: 4 threads (target='dev')
[2024-05-28T02:17:47.790+0000] {docker.py:354} INFO - [0m02:17:47
[2024-05-28T02:17:47.795+0000] {docker.py:354} INFO - [0m02:17:47  1 of 2 START sql table model dev.golden_data ................................... [RUN]
[2024-05-28T02:17:52.398+0000] {docker.py:354} INFO - [0m02:17:52  1 of 2 OK created sql table model dev.golden_data .............................. [[32mSELECT 323469[0m in 4.60s]
[2024-05-28T02:17:52.400+0000] {docker.py:354} INFO - [0m02:17:52  2 of 2 START sql table model dev.golden_mart_data .............................. [RUN]
[2024-05-28T02:17:52.422+0000] {docker.py:354} INFO - [0m02:17:52  2 of 2 ERROR creating sql table model dev.golden_mart_data ..................... [[31mERROR[0m in 0.02s]
[2024-05-28T02:17:52.521+0000] {docker.py:354} INFO - [0m02:17:52
[2024-05-28T02:17:52.522+0000] {docker.py:354} INFO - [0m02:17:52  Finished running 2 table models in 0 hours 0 minutes and 4.82 seconds (4.82s).
[2024-05-28T02:17:52.534+0000] {docker.py:354} INFO - [0m02:17:52
[2024-05-28T02:17:52.534+0000] {docker.py:354} INFO - [0m02:17:52  [31mCompleted with 1 error and 0 warnings:[0m
[2024-05-28T02:17:52.534+0000] {docker.py:354} INFO - [0m02:17:52
[2024-05-28T02:17:52.535+0000] {docker.py:354} INFO - [0m02:17:52  [33mDatabase Error in model golden_mart_data (models/golden/golden_mart_data.sql)[0m
[2024-05-28T02:17:52.535+0000] {docker.py:354} INFO - [0m02:17:52    function sum() does not exist
[2024-05-28T02:17:52.535+0000] {docker.py:354} INFO - [0m02:17:52    LINE 16:     sum(*) as cnt_2021_first_quarter
[2024-05-28T02:17:52.535+0000] {docker.py:354} INFO - [0m02:17:52                 ^
[2024-05-28T02:17:52.536+0000] {docker.py:354} INFO - [0m02:17:52    HINT:  No function matches the given name and argument types. You might need to add explicit type casts.
[2024-05-28T02:17:52.536+0000] {docker.py:354} INFO - [0m02:17:52    compiled Code at target/run/franko/models/golden/golden_mart_data.sql
[2024-05-28T02:17:52.536+0000] {docker.py:354} INFO - [0m02:17:52
[2024-05-28T02:17:52.536+0000] {docker.py:354} INFO - [0m02:17:52  Done. PASS=1 WARN=0 ERROR=1 SKIP=0 TOTAL=2
[2024-05-28T02:17:53.598+0000] {taskinstance.py:1772} ERROR - Task failed with exception
Traceback (most recent call last):
  File "/home/airflow/.local/lib/python3.7/site-packages/airflow/providers/docker/operators/docker.py", line 430, in execute
    return self._run_image()
  File "/home/airflow/.local/lib/python3.7/site-packages/airflow/providers/docker/operators/docker.py", line 303, in _run_image
    return self._run_image_with_mounts(self.mounts, add_tmp_variable=False)
  File "/home/airflow/.local/lib/python3.7/site-packages/airflow/providers/docker/operators/docker.py", line 359, in _run_image_with_mounts
    raise AirflowException(f"Docker container failed: {repr(result)} lines {joined_log_lines}")
airflow.exceptions.AirflowException: Docker container failed: {'StatusCode': 1} lines [0m02:17:47  Running with dbt=1.5.11
[0m02:17:47  Registered adapter: postgres=1.5.11
[0m02:17:47  Found 6 models, 4 tests, 0 snapshots, 0 analyses, 422 macros, 0 operations, 1 seed file, 1 source, 0 exposures, 0 metrics, 0 groups
[0m02:17:47
[0m02:17:47  Concurrency: 4 threads (target='dev')
[0m02:17:47
[0m02:17:47  1 of 2 START sql table model dev.golden_data ................................... [RUN]
[0m02:17:52  1 of 2 OK created sql table model dev.golden_data .............................. [[32mSELECT 323469[0m in 4.60s]
[0m02:17:52  2 of 2 START sql table model dev.golden_mart_data .............................. [RUN]
[0m02:17:52  2 of 2 ERROR creating sql table model dev.golden_mart_data ..................... [[31mERROR[0m in 0.02s]
[0m02:17:52
[0m02:17:52  Finished running 2 table models in 0 hours 0 minutes and 4.82 seconds (4.82s).
[0m02:17:52
[0m02:17:52  [31mCompleted with 1 error and 0 warnings:[0m
[0m02:17:52
[0m02:17:52  [33mDatabase Error in model golden_mart_data (models/golden/golden_mart_data.sql)[0m
[0m02:17:52    function sum() does not exist
[0m02:17:52    LINE 16:     sum(*) as cnt_2021_first_quarter
[0m02:17:52                 ^
[0m02:17:52    HINT:  No function matches the given name and argument types. You might need to add explicit type casts.
[0m02:17:52    compiled Code at target/run/franko/models/golden/golden_mart_data.sql
[0m02:17:52
[0m02:17:52  Done. PASS=1 WARN=0 ERROR=1 SKIP=0 TOTAL=2
[2024-05-28T02:17:53.602+0000] {taskinstance.py:1327} INFO - Marking task as FAILED. dag_id=franko_lookup_ingest, task_id=ti_load_target_data, execution_date=20240527T214908, start_date=20240528T021744, end_date=20240528T021753
[2024-05-28T02:17:53.616+0000] {standard_task_runner.py:105} ERROR - Failed to execute job 195 for task ti_load_target_data (Docker container failed: {'StatusCode': 1} lines [0m02:17:47  Running with dbt=1.5.11
[0m02:17:47  Registered adapter: postgres=1.5.11
[0m02:17:47  Found 6 models, 4 tests, 0 snapshots, 0 analyses, 422 macros, 0 operations, 1 seed file, 1 source, 0 exposures, 0 metrics, 0 groups
[0m02:17:47
[0m02:17:47  Concurrency: 4 threads (target='dev')
[0m02:17:47
[0m02:17:47  1 of 2 START sql table model dev.golden_data ................................... [RUN]
[0m02:17:52  1 of 2 OK created sql table model dev.golden_data .............................. [[32mSELECT 323469[0m in 4.60s]
[0m02:17:52  2 of 2 START sql table model dev.golden_mart_data .............................. [RUN]
[0m02:17:52  2 of 2 ERROR creating sql table model dev.golden_mart_data ..................... [[31mERROR[0m in 0.02s]
[0m02:17:52
[0m02:17:52  Finished running 2 table models in 0 hours 0 minutes and 4.82 seconds (4.82s).
[0m02:17:52
[0m02:17:52  [31mCompleted with 1 error and 0 warnings:[0m
[0m02:17:52
[0m02:17:52  [33mDatabase Error in model golden_mart_data (models/golden/golden_mart_data.sql)[0m
[0m02:17:52    function sum() does not exist
[0m02:17:52    LINE 16:     sum(*) as cnt_2021_first_quarter
[0m02:17:52                 ^
[0m02:17:52    HINT:  No function matches the given name and argument types. You might need to add explicit type casts.
[0m02:17:52    compiled Code at target/run/franko/models/golden/golden_mart_data.sql
[0m02:17:52
[0m02:17:52  Done. PASS=1 WARN=0 ERROR=1 SKIP=0 TOTAL=2; 6994)
[2024-05-28T02:17:53.635+0000] {local_task_job.py:159} INFO - Task exited with return code 1
[2024-05-28T02:17:53.659+0000] {taskinstance.py:2582} INFO - 0 downstream tasks scheduled from follow-on schedule check
