[2024-05-28T02:31:09.906+0000] {taskinstance.py:1087} INFO - Dependencies all met for <TaskInstance: franko_lookup_ingest.ti_load_target_data manual__2024-05-27T21:49:08.726117+00:00 [queued]>
[2024-05-28T02:31:09.914+0000] {taskinstance.py:1087} INFO - Dependencies all met for <TaskInstance: franko_lookup_ingest.ti_load_target_data manual__2024-05-27T21:49:08.726117+00:00 [queued]>
[2024-05-28T02:31:09.914+0000] {taskinstance.py:1283} INFO - 
--------------------------------------------------------------------------------
[2024-05-28T02:31:09.914+0000] {taskinstance.py:1284} INFO - Starting attempt 20 of 20
[2024-05-28T02:31:09.914+0000] {taskinstance.py:1285} INFO - 
--------------------------------------------------------------------------------
[2024-05-28T02:31:09.928+0000] {taskinstance.py:1304} INFO - Executing <Task(DockerOperator): ti_load_target_data> on 2024-05-27 21:49:08.726117+00:00
[2024-05-28T02:31:09.932+0000] {standard_task_runner.py:55} INFO - Started process 296 to run task
[2024-05-28T02:31:09.934+0000] {standard_task_runner.py:82} INFO - Running: ['***', 'tasks', 'run', 'franko_lookup_ingest', 'ti_load_target_data', 'manual__2024-05-27T21:49:08.726117+00:00', '--job-id', '231', '--raw', '--subdir', 'DAGS_FOLDER/challenge_dag.py', '--cfg-path', '/tmp/tmpconsdqen']
[2024-05-28T02:31:09.934+0000] {standard_task_runner.py:83} INFO - Job 231: Subtask ti_load_target_data
[2024-05-28T02:31:09.992+0000] {task_command.py:389} INFO - Running <TaskInstance: franko_lookup_ingest.ti_load_target_data manual__2024-05-27T21:49:08.726117+00:00 [running]> on host a64b6410e10e
[2024-05-28T02:31:10.060+0000] {taskinstance.py:1513} INFO - Exporting the following env vars:
AIRFLOW_CTX_DAG_OWNER=***
AIRFLOW_CTX_DAG_ID=franko_lookup_ingest
AIRFLOW_CTX_TASK_ID=ti_load_target_data
AIRFLOW_CTX_EXECUTION_DATE=2024-05-27T21:49:08.726117+00:00
AIRFLOW_CTX_TRY_NUMBER=20
AIRFLOW_CTX_DAG_RUN_ID=manual__2024-05-27T21:49:08.726117+00:00
[2024-05-28T02:31:10.064+0000] {taskinstance.py:1772} ERROR - Task failed with exception
Traceback (most recent call last):
  File "/home/airflow/.local/lib/python3.7/site-packages/urllib3/connectionpool.py", line 710, in urlopen
    chunked=chunked,
  File "/home/airflow/.local/lib/python3.7/site-packages/urllib3/connectionpool.py", line 398, in _make_request
    conn.request(method, url, **httplib_request_kw)
  File "/usr/local/lib/python3.7/http/client.py", line 1281, in request
    self._send_request(method, url, body, headers, encode_chunked)
  File "/usr/local/lib/python3.7/http/client.py", line 1327, in _send_request
    self.endheaders(body, encode_chunked=encode_chunked)
  File "/usr/local/lib/python3.7/http/client.py", line 1276, in endheaders
    self._send_output(message_body, encode_chunked=encode_chunked)
  File "/usr/local/lib/python3.7/http/client.py", line 1036, in _send_output
    self.send(msg)
  File "/usr/local/lib/python3.7/http/client.py", line 976, in send
    self.connect()
  File "/home/airflow/.local/lib/python3.7/site-packages/docker/transport/unixconn.py", line 30, in connect
    sock.connect(self.unix_socket)
PermissionError: [Errno 13] Permission denied

During handling of the above exception, another exception occurred:

Traceback (most recent call last):
  File "/home/airflow/.local/lib/python3.7/site-packages/requests/adapters.py", line 499, in send
    timeout=timeout,
  File "/home/airflow/.local/lib/python3.7/site-packages/urllib3/connectionpool.py", line 788, in urlopen
    method, url, error=e, _pool=self, _stacktrace=sys.exc_info()[2]
  File "/home/airflow/.local/lib/python3.7/site-packages/urllib3/util/retry.py", line 550, in increment
    raise six.reraise(type(error), error, _stacktrace)
  File "/home/airflow/.local/lib/python3.7/site-packages/urllib3/packages/six.py", line 769, in reraise
    raise value.with_traceback(tb)
  File "/home/airflow/.local/lib/python3.7/site-packages/urllib3/connectionpool.py", line 710, in urlopen
    chunked=chunked,
  File "/home/airflow/.local/lib/python3.7/site-packages/urllib3/connectionpool.py", line 398, in _make_request
    conn.request(method, url, **httplib_request_kw)
  File "/usr/local/lib/python3.7/http/client.py", line 1281, in request
    self._send_request(method, url, body, headers, encode_chunked)
  File "/usr/local/lib/python3.7/http/client.py", line 1327, in _send_request
    self.endheaders(body, encode_chunked=encode_chunked)
  File "/usr/local/lib/python3.7/http/client.py", line 1276, in endheaders
    self._send_output(message_body, encode_chunked=encode_chunked)
  File "/usr/local/lib/python3.7/http/client.py", line 1036, in _send_output
    self.send(msg)
  File "/usr/local/lib/python3.7/http/client.py", line 976, in send
    self.connect()
  File "/home/airflow/.local/lib/python3.7/site-packages/docker/transport/unixconn.py", line 30, in connect
    sock.connect(self.unix_socket)
urllib3.exceptions.ProtocolError: ('Connection aborted.', PermissionError(13, 'Permission denied'))

During handling of the above exception, another exception occurred:

Traceback (most recent call last):
  File "/home/airflow/.local/lib/python3.7/site-packages/docker/api/client.py", line 214, in _retrieve_server_version
    return self.version(api_version=False)["ApiVersion"]
  File "/home/airflow/.local/lib/python3.7/site-packages/docker/api/daemon.py", line 181, in version
    return self._result(self._get(url), json=True)
  File "/home/airflow/.local/lib/python3.7/site-packages/docker/utils/decorators.py", line 46, in inner
    return f(self, *args, **kwargs)
  File "/home/airflow/.local/lib/python3.7/site-packages/docker/api/client.py", line 237, in _get
    return self.get(url, **self._set_request_timeout(kwargs))
  File "/home/airflow/.local/lib/python3.7/site-packages/requests/sessions.py", line 600, in get
    return self.request("GET", url, **kwargs)
  File "/home/airflow/.local/lib/python3.7/site-packages/requests/sessions.py", line 587, in request
    resp = self.send(prep, **send_kwargs)
  File "/home/airflow/.local/lib/python3.7/site-packages/requests/sessions.py", line 701, in send
    r = adapter.send(request, **kwargs)
  File "/home/airflow/.local/lib/python3.7/site-packages/requests/adapters.py", line 547, in send
    raise ConnectionError(err, request=request)
requests.exceptions.ConnectionError: ('Connection aborted.', PermissionError(13, 'Permission denied'))

During handling of the above exception, another exception occurred:

Traceback (most recent call last):
  File "/home/airflow/.local/lib/python3.7/site-packages/airflow/providers/docker/operators/docker.py", line 407, in execute
    self.cli = self._get_cli()
  File "/home/airflow/.local/lib/python3.7/site-packages/airflow/providers/docker/operators/docker.py", line 438, in _get_cli
    base_url=self.docker_url, version=self.api_version, tls=tls_config, timeout=self.timeout
  File "/home/airflow/.local/lib/python3.7/site-packages/docker/api/client.py", line 197, in __init__
    self._version = self._retrieve_server_version()
  File "/home/airflow/.local/lib/python3.7/site-packages/docker/api/client.py", line 222, in _retrieve_server_version
    f'Error while fetching server API version: {e}'
docker.errors.DockerException: Error while fetching server API version: ('Connection aborted.', PermissionError(13, 'Permission denied'))
[2024-05-28T02:31:10.074+0000] {taskinstance.py:1327} INFO - Marking task as FAILED. dag_id=franko_lookup_ingest, task_id=ti_load_target_data, execution_date=20240527T214908, start_date=20240528T023109, end_date=20240528T023110
[2024-05-28T02:31:10.084+0000] {standard_task_runner.py:105} ERROR - Failed to execute job 231 for task ti_load_target_data (Error while fetching server API version: ('Connection aborted.', PermissionError(13, 'Permission denied')); 296)
[2024-05-28T02:31:10.106+0000] {local_task_job.py:159} INFO - Task exited with return code 1
[2024-05-28T02:31:10.121+0000] {taskinstance.py:2582} INFO - 0 downstream tasks scheduled from follow-on schedule check
