[2024-05-28T00:15:37.925+0000] {taskinstance.py:1087} INFO - Dependencies all met for <TaskInstance: franko_lookup_ingest.ti_load_target_data manual__2024-05-27T21:49:08.726117+00:00 [queued]>
[2024-05-28T00:15:37.937+0000] {taskinstance.py:1087} INFO - Dependencies all met for <TaskInstance: franko_lookup_ingest.ti_load_target_data manual__2024-05-27T21:49:08.726117+00:00 [queued]>
[2024-05-28T00:15:37.937+0000] {taskinstance.py:1283} INFO - 
--------------------------------------------------------------------------------
[2024-05-28T00:15:37.937+0000] {taskinstance.py:1284} INFO - Starting attempt 9 of 9
[2024-05-28T00:15:37.937+0000] {taskinstance.py:1285} INFO - 
--------------------------------------------------------------------------------
[2024-05-28T00:15:37.958+0000] {taskinstance.py:1304} INFO - Executing <Task(DockerOperator): ti_load_target_data> on 2024-05-27 21:49:08.726117+00:00
[2024-05-28T00:15:37.963+0000] {standard_task_runner.py:55} INFO - Started process 73 to run task
[2024-05-28T00:15:37.966+0000] {standard_task_runner.py:82} INFO - Running: ['***', 'tasks', 'run', 'franko_lookup_ingest', 'ti_load_target_data', 'manual__2024-05-27T21:49:08.726117+00:00', '--job-id', '185', '--raw', '--subdir', 'DAGS_FOLDER/challenge_dag.py', '--cfg-path', '/tmp/tmpl6kq5cwk']
[2024-05-28T00:15:37.967+0000] {standard_task_runner.py:83} INFO - Job 185: Subtask ti_load_target_data
[2024-05-28T00:15:38.027+0000] {task_command.py:389} INFO - Running <TaskInstance: franko_lookup_ingest.ti_load_target_data manual__2024-05-27T21:49:08.726117+00:00 [running]> on host a64b6410e10e
[2024-05-28T00:15:38.100+0000] {taskinstance.py:1513} INFO - Exporting the following env vars:
AIRFLOW_CTX_DAG_OWNER=***
AIRFLOW_CTX_DAG_ID=franko_lookup_ingest
AIRFLOW_CTX_TASK_ID=ti_load_target_data
AIRFLOW_CTX_EXECUTION_DATE=2024-05-27T21:49:08.726117+00:00
AIRFLOW_CTX_TRY_NUMBER=9
AIRFLOW_CTX_DAG_RUN_ID=manual__2024-05-27T21:49:08.726117+00:00
[2024-05-28T00:15:38.130+0000] {docker.py:284} INFO - Starting docker container from image my_dbt
[2024-05-28T00:15:40.737+0000] {docker.py:354} INFO - [0m00:15:40  Running with dbt=1.5.11
[2024-05-28T00:15:40.929+0000] {docker.py:354} INFO - [0m00:15:40  Registered adapter: postgres=1.5.11
[2024-05-28T00:15:41.086+0000] {docker.py:354} INFO - [0m00:15:41  Found 5 models, 4 tests, 0 snapshots, 0 analyses, 422 macros, 0 operations, 1 seed file, 1 source, 0 exposures, 0 metrics, 0 groups
[2024-05-28T00:15:41.089+0000] {docker.py:354} INFO - [0m00:15:41
[2024-05-28T00:15:41.207+0000] {docker.py:354} INFO - [0m00:15:41  Concurrency: 4 threads (target='dev')
[2024-05-28T00:15:41.207+0000] {docker.py:354} INFO - [0m00:15:41
[2024-05-28T00:15:41.212+0000] {docker.py:354} INFO - [0m00:15:41  1 of 1 START sql table model dev.golden_data ................................... [RUN]
[2024-05-28T00:54:43.009+0000] {docker.py:354} INFO - [0m00:54:42  1 of 1 ERROR creating sql table model dev.golden_data .......................... [[31mERROR[0m in 2341.74s]
[2024-05-28T00:54:43.218+0000] {docker.py:354} INFO - [0m00:54:43  Database error while running on-run-end
[2024-05-28T00:54:43.224+0000] {docker.py:354} INFO - [0m00:54:43
[2024-05-28T00:54:43.230+0000] {docker.py:354} INFO - [0m00:54:43  Finished running 1 table model in 0 hours 39 minutes and 2.13 seconds (2342.13s).
[2024-05-28T00:54:43.274+0000] {docker.py:354} INFO - [0m00:54:43
[2024-05-28T00:54:43.280+0000] {docker.py:354} INFO - [0m00:54:43  [31mCompleted with 2 errors and 0 warnings:[0m
[2024-05-28T00:54:43.280+0000] {docker.py:354} INFO - [0m00:54:43
[2024-05-28T00:54:43.281+0000] {docker.py:354} INFO - [0m00:54:43  [33mDatabase Error in model golden_data (models/golden/golden_data.sql)[0m
[2024-05-28T00:54:43.282+0000] {docker.py:354} INFO - [0m00:54:43    server closed the connection unexpectedly
[2024-05-28T00:54:43.283+0000] {docker.py:354} INFO - [0m00:54:43    	This probably means the server terminated abnormally
[2024-05-28T00:54:43.283+0000] {docker.py:354} INFO - [0m00:54:43    	before or while processing the request.
[2024-05-28T00:54:43.284+0000] {docker.py:354} INFO - [0m00:54:43    compiled Code at target/run/franko/models/golden/golden_data.sql
[2024-05-28T00:54:43.284+0000] {docker.py:354} INFO - [0m00:54:43
[2024-05-28T00:54:43.285+0000] {docker.py:354} INFO - [0m00:54:43  [33mon-run-end failed, error:[0m
[2024-05-28T00:54:43.285+0000] {docker.py:354} INFO - [0m00:54:43   connection to server at "frankomiguel-challenge-my_wh-1" (172.20.0.2), port 5432 failed: FATAL:  the database system is in recovery mode
[2024-05-28T00:54:43.286+0000] {docker.py:354} INFO - [0m00:54:43
[2024-05-28T00:54:43.286+0000] {docker.py:354} INFO - [0m00:54:43
[2024-05-28T00:54:43.287+0000] {docker.py:354} INFO - [0m00:54:43  Done. PASS=0 WARN=0 ERROR=2 SKIP=0 TOTAL=2
[2024-05-28T00:54:44.170+0000] {taskinstance.py:1772} ERROR - Task failed with exception
Traceback (most recent call last):
  File "/home/airflow/.local/lib/python3.7/site-packages/airflow/providers/docker/operators/docker.py", line 430, in execute
    return self._run_image()
  File "/home/airflow/.local/lib/python3.7/site-packages/airflow/providers/docker/operators/docker.py", line 303, in _run_image
    return self._run_image_with_mounts(self.mounts, add_tmp_variable=False)
  File "/home/airflow/.local/lib/python3.7/site-packages/airflow/providers/docker/operators/docker.py", line 359, in _run_image_with_mounts
    raise AirflowException(f"Docker container failed: {repr(result)} lines {joined_log_lines}")
airflow.exceptions.AirflowException: Docker container failed: {'StatusCode': 1} lines [0m00:15:40  Running with dbt=1.5.11
[0m00:15:40  Registered adapter: postgres=1.5.11
[0m00:15:41  Found 5 models, 4 tests, 0 snapshots, 0 analyses, 422 macros, 0 operations, 1 seed file, 1 source, 0 exposures, 0 metrics, 0 groups
[0m00:15:41
[0m00:15:41  Concurrency: 4 threads (target='dev')
[0m00:15:41
[0m00:15:41  1 of 1 START sql table model dev.golden_data ................................... [RUN]
[0m00:54:42  1 of 1 ERROR creating sql table model dev.golden_data .......................... [[31mERROR[0m in 2341.74s]
[0m00:54:43  Database error while running on-run-end
[0m00:54:43
[0m00:54:43  Finished running 1 table model in 0 hours 39 minutes and 2.13 seconds (2342.13s).
[0m00:54:43
[0m00:54:43  [31mCompleted with 2 errors and 0 warnings:[0m
[0m00:54:43
[0m00:54:43  [33mDatabase Error in model golden_data (models/golden/golden_data.sql)[0m
[0m00:54:43    server closed the connection unexpectedly
[0m00:54:43    	This probably means the server terminated abnormally
[0m00:54:43    	before or while processing the request.
[0m00:54:43    compiled Code at target/run/franko/models/golden/golden_data.sql
[0m00:54:43
[0m00:54:43  [33mon-run-end failed, error:[0m
[0m00:54:43   connection to server at "frankomiguel-challenge-my_wh-1" (172.20.0.2), port 5432 failed: FATAL:  the database system is in recovery mode
[0m00:54:43
[0m00:54:43
[0m00:54:43  Done. PASS=0 WARN=0 ERROR=2 SKIP=0 TOTAL=2
[2024-05-28T00:54:44.194+0000] {taskinstance.py:1327} INFO - Marking task as FAILED. dag_id=franko_lookup_ingest, task_id=ti_load_target_data, execution_date=20240527T214908, start_date=20240528T001537, end_date=20240528T005444
[2024-05-28T00:54:44.258+0000] {standard_task_runner.py:105} ERROR - Failed to execute job 185 for task ti_load_target_data (Docker container failed: {'StatusCode': 1} lines [0m00:15:40  Running with dbt=1.5.11
[0m00:15:40  Registered adapter: postgres=1.5.11
[0m00:15:41  Found 5 models, 4 tests, 0 snapshots, 0 analyses, 422 macros, 0 operations, 1 seed file, 1 source, 0 exposures, 0 metrics, 0 groups
[0m00:15:41
[0m00:15:41  Concurrency: 4 threads (target='dev')
[0m00:15:41
[0m00:15:41  1 of 1 START sql table model dev.golden_data ................................... [RUN]
[0m00:54:42  1 of 1 ERROR creating sql table model dev.golden_data .......................... [[31mERROR[0m in 2341.74s]
[0m00:54:43  Database error while running on-run-end
[0m00:54:43
[0m00:54:43  Finished running 1 table model in 0 hours 39 minutes and 2.13 seconds (2342.13s).
[0m00:54:43
[0m00:54:43  [31mCompleted with 2 errors and 0 warnings:[0m
[0m00:54:43
[0m00:54:43  [33mDatabase Error in model golden_data (models/golden/golden_data.sql)[0m
[0m00:54:43    server closed the connection unexpectedly
[0m00:54:43    	This probably means the server terminated abnormally
[0m00:54:43    	before or while processing the request.
[0m00:54:43    compiled Code at target/run/franko/models/golden/golden_data.sql
[0m00:54:43
[0m00:54:43  [33mon-run-end failed, error:[0m
[0m00:54:43   connection to server at "frankomiguel-challenge-my_wh-1" (172.20.0.2), port 5432 failed: FATAL:  the database system is in recovery mode
[0m00:54:43
[0m00:54:43
[0m00:54:43  Done. PASS=0 WARN=0 ERROR=2 SKIP=0 TOTAL=2; 73)
[2024-05-28T00:54:44.305+0000] {local_task_job.py:159} INFO - Task exited with return code 1
[2024-05-28T00:54:44.372+0000] {taskinstance.py:2582} INFO - 0 downstream tasks scheduled from follow-on schedule check
