[2024-05-27T21:52:28.185+0000] {taskinstance.py:1087} INFO - Dependencies all met for <TaskInstance: franko_lookup_ingest.ti_load_raw_data manual__2024-05-27T21:49:08.726117+00:00 [queued]>
[2024-05-27T21:52:28.203+0000] {taskinstance.py:1087} INFO - Dependencies all met for <TaskInstance: franko_lookup_ingest.ti_load_raw_data manual__2024-05-27T21:49:08.726117+00:00 [queued]>
[2024-05-27T21:52:28.204+0000] {taskinstance.py:1283} INFO - 
--------------------------------------------------------------------------------
[2024-05-27T21:52:28.204+0000] {taskinstance.py:1284} INFO - Starting attempt 3 of 3
[2024-05-27T21:52:28.204+0000] {taskinstance.py:1285} INFO - 
--------------------------------------------------------------------------------
[2024-05-27T21:52:28.230+0000] {taskinstance.py:1304} INFO - Executing <Task(DockerOperator): ti_load_raw_data> on 2024-05-27 21:49:08.726117+00:00
[2024-05-27T21:52:28.238+0000] {standard_task_runner.py:55} INFO - Started process 9320 to run task
[2024-05-27T21:52:28.242+0000] {standard_task_runner.py:82} INFO - Running: ['***', 'tasks', 'run', 'franko_lookup_ingest', 'ti_load_raw_data', 'manual__2024-05-27T21:49:08.726117+00:00', '--job-id', '85', '--raw', '--subdir', 'DAGS_FOLDER/challenge_dag.py', '--cfg-path', '/tmp/tmpentept6o']
[2024-05-27T21:52:28.243+0000] {standard_task_runner.py:83} INFO - Job 85: Subtask ti_load_raw_data
[2024-05-27T21:52:28.341+0000] {task_command.py:389} INFO - Running <TaskInstance: franko_lookup_ingest.ti_load_raw_data manual__2024-05-27T21:49:08.726117+00:00 [running]> on host a64b6410e10e
[2024-05-27T21:52:28.456+0000] {taskinstance.py:1513} INFO - Exporting the following env vars:
AIRFLOW_CTX_DAG_OWNER=***
AIRFLOW_CTX_DAG_ID=franko_lookup_ingest
AIRFLOW_CTX_TASK_ID=ti_load_raw_data
AIRFLOW_CTX_EXECUTION_DATE=2024-05-27T21:49:08.726117+00:00
AIRFLOW_CTX_TRY_NUMBER=3
AIRFLOW_CTX_DAG_RUN_ID=manual__2024-05-27T21:49:08.726117+00:00
[2024-05-27T21:52:28.486+0000] {docker.py:284} INFO - Starting docker container from image my_dbt
[2024-05-27T21:52:31.450+0000] {docker.py:354} INFO - [0m21:52:31  Running with dbt=1.5.11
[2024-05-27T21:52:31.587+0000] {docker.py:354} INFO - [0m21:52:31  Registered adapter: postgres=1.5.11
[2024-05-27T21:52:31.694+0000] {docker.py:354} INFO - [0m21:52:31  Encountered an error:
Compilation Error
  Model 'model.franko.silver_covid_geo' (models/silver/silver_covid_geo.sql) depends on a node named 'silver_dataset' which was not found
[2024-05-27T21:52:32.593+0000] {taskinstance.py:1772} ERROR - Task failed with exception
Traceback (most recent call last):
  File "/home/airflow/.local/lib/python3.7/site-packages/airflow/providers/docker/operators/docker.py", line 430, in execute
    return self._run_image()
  File "/home/airflow/.local/lib/python3.7/site-packages/airflow/providers/docker/operators/docker.py", line 303, in _run_image
    return self._run_image_with_mounts(self.mounts, add_tmp_variable=False)
  File "/home/airflow/.local/lib/python3.7/site-packages/airflow/providers/docker/operators/docker.py", line 359, in _run_image_with_mounts
    raise AirflowException(f"Docker container failed: {repr(result)} lines {joined_log_lines}")
airflow.exceptions.AirflowException: Docker container failed: {'StatusCode': 2} lines [0m21:52:31  Running with dbt=1.5.11
[0m21:52:31  Registered adapter: postgres=1.5.11
[0m21:52:31  Encountered an error:
Compilation Error
  Model 'model.franko.silver_covid_geo' (models/silver/silver_covid_geo.sql) depends on a node named 'silver_dataset' which was not found
[2024-05-27T21:52:32.595+0000] {taskinstance.py:1327} INFO - Marking task as FAILED. dag_id=franko_lookup_ingest, task_id=ti_load_raw_data, execution_date=20240527T214908, start_date=20240527T215228, end_date=20240527T215232
[2024-05-27T21:52:32.606+0000] {standard_task_runner.py:105} ERROR - Failed to execute job 85 for task ti_load_raw_data (Docker container failed: {'StatusCode': 2} lines [0m21:52:31  Running with dbt=1.5.11
[0m21:52:31  Registered adapter: postgres=1.5.11
[0m21:52:31  Encountered an error:
Compilation Error
  Model 'model.franko.silver_covid_geo' (models/silver/silver_covid_geo.sql) depends on a node named 'silver_dataset' which was not found; 9320)
[2024-05-27T21:52:32.638+0000] {local_task_job.py:159} INFO - Task exited with return code 1
[2024-05-27T21:52:32.675+0000] {taskinstance.py:2582} INFO - 0 downstream tasks scheduled from follow-on schedule check
