[2024-05-28T03:16:01.082+0000] {taskinstance.py:1087} INFO - Dependencies all met for <TaskInstance: franko_lookup_ingest.ti_docs_generate scheduled__2024-05-26T08:00:00+00:00 [queued]>
[2024-05-28T03:16:01.093+0000] {taskinstance.py:1087} INFO - Dependencies all met for <TaskInstance: franko_lookup_ingest.ti_docs_generate scheduled__2024-05-26T08:00:00+00:00 [queued]>
[2024-05-28T03:16:01.093+0000] {taskinstance.py:1283} INFO - 
--------------------------------------------------------------------------------
[2024-05-28T03:16:01.093+0000] {taskinstance.py:1284} INFO - Starting attempt 2 of 2
[2024-05-28T03:16:01.094+0000] {taskinstance.py:1285} INFO - 
--------------------------------------------------------------------------------
[2024-05-28T03:16:01.109+0000] {taskinstance.py:1304} INFO - Executing <Task(DockerOperator): ti_docs_generate> on 2024-05-26 08:00:00+00:00
[2024-05-28T03:16:01.115+0000] {standard_task_runner.py:55} INFO - Started process 1263 to run task
[2024-05-28T03:16:01.118+0000] {standard_task_runner.py:82} INFO - Running: ['***', 'tasks', 'run', 'franko_lookup_ingest', 'ti_docs_generate', 'scheduled__2024-05-26T08:00:00+00:00', '--job-id', '282', '--raw', '--subdir', 'DAGS_FOLDER/challenge_dag.py', '--cfg-path', '/tmp/tmpt2dukhnd']
[2024-05-28T03:16:01.119+0000] {standard_task_runner.py:83} INFO - Job 282: Subtask ti_docs_generate
[2024-05-28T03:16:01.191+0000] {task_command.py:389} INFO - Running <TaskInstance: franko_lookup_ingest.ti_docs_generate scheduled__2024-05-26T08:00:00+00:00 [running]> on host a64b6410e10e
[2024-05-28T03:16:01.313+0000] {taskinstance.py:1513} INFO - Exporting the following env vars:
AIRFLOW_CTX_DAG_OWNER=***
AIRFLOW_CTX_DAG_ID=franko_lookup_ingest
AIRFLOW_CTX_TASK_ID=ti_docs_generate
AIRFLOW_CTX_EXECUTION_DATE=2024-05-26T08:00:00+00:00
AIRFLOW_CTX_TRY_NUMBER=2
AIRFLOW_CTX_DAG_RUN_ID=scheduled__2024-05-26T08:00:00+00:00
[2024-05-28T03:16:01.344+0000] {docker.py:284} INFO - Starting docker container from image my_dbt
[2024-05-28T03:16:04.020+0000] {docker.py:354} INFO - Usage: dbt docs generate [OPTIONS]
Try 'dbt docs generate -h' for help.

Error: No such option: --port (Possible options: --no-print, --print)
[2024-05-28T03:16:04.174+0000] {taskinstance.py:1772} ERROR - Task failed with exception
Traceback (most recent call last):
  File "/home/airflow/.local/lib/python3.7/site-packages/airflow/providers/docker/operators/docker.py", line 430, in execute
    return self._run_image()
  File "/home/airflow/.local/lib/python3.7/site-packages/airflow/providers/docker/operators/docker.py", line 303, in _run_image
    return self._run_image_with_mounts(self.mounts, add_tmp_variable=False)
  File "/home/airflow/.local/lib/python3.7/site-packages/airflow/providers/docker/operators/docker.py", line 359, in _run_image_with_mounts
    raise AirflowException(f"Docker container failed: {repr(result)} lines {joined_log_lines}")
airflow.exceptions.AirflowException: Docker container failed: {'StatusCode': 2} lines Usage: dbt docs generate [OPTIONS]
Try 'dbt docs generate -h' for help.

Error: No such option: --port (Possible options: --no-print, --print)
[2024-05-28T03:16:04.182+0000] {taskinstance.py:1327} INFO - Marking task as FAILED. dag_id=franko_lookup_ingest, task_id=ti_docs_generate, execution_date=20240526T080000, start_date=20240528T031601, end_date=20240528T031604
[2024-05-28T03:16:04.202+0000] {standard_task_runner.py:105} ERROR - Failed to execute job 282 for task ti_docs_generate (Docker container failed: {'StatusCode': 2} lines Usage: dbt docs generate [OPTIONS]
Try 'dbt docs generate -h' for help.

Error: No such option: --port (Possible options: --no-print, --print); 1263)
[2024-05-28T03:16:04.227+0000] {local_task_job.py:159} INFO - Task exited with return code 1
[2024-05-28T03:16:04.253+0000] {taskinstance.py:2582} INFO - 0 downstream tasks scheduled from follow-on schedule check
