[2024-05-25T03:15:34.313+0000] {taskinstance.py:1087} INFO - Dependencies all met for <TaskInstance: franko_python.create_seeds manual__2024-05-25T02:02:40.608195+00:00 [queued]>
[2024-05-25T03:15:34.329+0000] {taskinstance.py:1087} INFO - Dependencies all met for <TaskInstance: franko_python.create_seeds manual__2024-05-25T02:02:40.608195+00:00 [queued]>
[2024-05-25T03:15:34.329+0000] {taskinstance.py:1283} INFO - 
--------------------------------------------------------------------------------
[2024-05-25T03:15:34.330+0000] {taskinstance.py:1284} INFO - Starting attempt 4 of 4
[2024-05-25T03:15:34.330+0000] {taskinstance.py:1285} INFO - 
--------------------------------------------------------------------------------
[2024-05-25T03:15:34.357+0000] {taskinstance.py:1304} INFO - Executing <Task(DockerOperator): create_seeds> on 2024-05-25 02:02:40.608195+00:00
[2024-05-25T03:15:34.369+0000] {standard_task_runner.py:55} INFO - Started process 281 to run task
[2024-05-25T03:15:34.392+0000] {standard_task_runner.py:82} INFO - Running: ['***', 'tasks', 'run', 'franko_python', 'create_seeds', 'manual__2024-05-25T02:02:40.608195+00:00', '--job-id', '15', '--raw', '--subdir', 'DAGS_FOLDER/example_dag.py', '--cfg-path', '/tmp/tmp262n1l65']
[2024-05-25T03:15:34.397+0000] {standard_task_runner.py:83} INFO - Job 15: Subtask create_seeds
[2024-05-25T03:15:34.490+0000] {task_command.py:389} INFO - Running <TaskInstance: franko_python.create_seeds manual__2024-05-25T02:02:40.608195+00:00 [running]> on host b637b51b94ee
[2024-05-25T03:15:34.618+0000] {taskinstance.py:1513} INFO - Exporting the following env vars:
AIRFLOW_CTX_DAG_OWNER=***
AIRFLOW_CTX_DAG_ID=franko_python
AIRFLOW_CTX_TASK_ID=create_seeds
AIRFLOW_CTX_EXECUTION_DATE=2024-05-25T02:02:40.608195+00:00
AIRFLOW_CTX_TRY_NUMBER=4
AIRFLOW_CTX_DAG_RUN_ID=manual__2024-05-25T02:02:40.608195+00:00
[2024-05-25T03:15:34.715+0000] {docker.py:414} INFO - Pulling docker image custom_dbt_image
[2024-05-25T03:15:38.385+0000] {taskinstance.py:1772} ERROR - Task failed with exception
Traceback (most recent call last):
  File "/home/airflow/.local/lib/python3.7/site-packages/docker/api/client.py", line 268, in _raise_for_status
    response.raise_for_status()
  File "/home/airflow/.local/lib/python3.7/site-packages/requests/models.py", line 1021, in raise_for_status
    raise HTTPError(http_error_msg, response=self)
requests.exceptions.HTTPError: 404 Client Error: Not Found for url: http+docker://localhost/v1.43/images/create?tag=latest&fromImage=custom_dbt_image

The above exception was the direct cause of the following exception:

Traceback (most recent call last):
  File "/home/airflow/.local/lib/python3.7/site-packages/airflow/providers/docker/operators/docker.py", line 416, in execute
    for output in self.cli.pull(self.image, stream=True, decode=True):
  File "/home/airflow/.local/lib/python3.7/site-packages/docker/api/image.py", line 429, in pull
    self._raise_for_status(response)
  File "/home/airflow/.local/lib/python3.7/site-packages/docker/api/client.py", line 270, in _raise_for_status
    raise create_api_error_from_http_exception(e) from e
  File "/home/airflow/.local/lib/python3.7/site-packages/docker/errors.py", line 39, in create_api_error_from_http_exception
    raise cls(e, response=response, explanation=explanation) from e
docker.errors.ImageNotFound: 404 Client Error for http+docker://localhost/v1.43/images/create?tag=latest&fromImage=custom_dbt_image: Not Found ("pull access denied for custom_dbt_image, repository does not exist or may require 'docker login': denied: requested access to the resource is denied")
[2024-05-25T03:15:38.392+0000] {taskinstance.py:1327} INFO - Marking task as FAILED. dag_id=franko_python, task_id=create_seeds, execution_date=20240525T020240, start_date=20240525T031534, end_date=20240525T031538
[2024-05-25T03:15:38.405+0000] {standard_task_runner.py:105} ERROR - Failed to execute job 15 for task create_seeds (404 Client Error for http+docker://localhost/v1.43/images/create?tag=latest&fromImage=custom_dbt_image: Not Found ("pull access denied for custom_dbt_image, repository does not exist or may require 'docker login': denied: requested access to the resource is denied"); 281)
[2024-05-25T03:15:38.425+0000] {local_task_job.py:159} INFO - Task exited with return code 1
[2024-05-25T03:15:38.452+0000] {taskinstance.py:2582} INFO - 0 downstream tasks scheduled from follow-on schedule check
