[2024-05-27T18:26:12.554+0000] {taskinstance.py:1087} INFO - Dependencies all met for <TaskInstance: franko_python.create_seeds manual__2024-05-25T02:02:40.608195+00:00 [queued]>
[2024-05-27T18:26:12.564+0000] {taskinstance.py:1087} INFO - Dependencies all met for <TaskInstance: franko_python.create_seeds manual__2024-05-25T02:02:40.608195+00:00 [queued]>
[2024-05-27T18:26:12.564+0000] {taskinstance.py:1283} INFO - 
--------------------------------------------------------------------------------
[2024-05-27T18:26:12.564+0000] {taskinstance.py:1284} INFO - Starting attempt 22 of 22
[2024-05-27T18:26:12.564+0000] {taskinstance.py:1285} INFO - 
--------------------------------------------------------------------------------
[2024-05-27T18:26:12.580+0000] {taskinstance.py:1304} INFO - Executing <Task(DockerOperator): create_seeds> on 2024-05-25 02:02:40.608195+00:00
[2024-05-27T18:26:12.585+0000] {standard_task_runner.py:55} INFO - Started process 1592 to run task
[2024-05-27T18:26:12.588+0000] {standard_task_runner.py:82} INFO - Running: ['***', 'tasks', 'run', 'franko_python', 'create_seeds', 'manual__2024-05-25T02:02:40.608195+00:00', '--job-id', '50', '--raw', '--subdir', 'DAGS_FOLDER/example_dag.py', '--cfg-path', '/tmp/tmplbcr5p3c']
[2024-05-27T18:26:12.589+0000] {standard_task_runner.py:83} INFO - Job 50: Subtask create_seeds
[2024-05-27T18:26:12.642+0000] {task_command.py:389} INFO - Running <TaskInstance: franko_python.create_seeds manual__2024-05-25T02:02:40.608195+00:00 [running]> on host b637b51b94ee
[2024-05-27T18:26:12.703+0000] {taskinstance.py:1513} INFO - Exporting the following env vars:
AIRFLOW_CTX_DAG_OWNER=***
AIRFLOW_CTX_DAG_ID=franko_python
AIRFLOW_CTX_TASK_ID=create_seeds
AIRFLOW_CTX_EXECUTION_DATE=2024-05-25T02:02:40.608195+00:00
AIRFLOW_CTX_TRY_NUMBER=22
AIRFLOW_CTX_DAG_RUN_ID=manual__2024-05-25T02:02:40.608195+00:00
[2024-05-27T18:26:12.721+0000] {docker.py:284} INFO - Starting docker container from image my_dbt
[2024-05-27T18:26:12.756+0000] {taskinstance.py:1772} ERROR - Task failed with exception
Traceback (most recent call last):
  File "/home/airflow/.local/lib/python3.7/site-packages/docker/api/client.py", line 268, in _raise_for_status
    response.raise_for_status()
  File "/home/airflow/.local/lib/python3.7/site-packages/requests/models.py", line 1021, in raise_for_status
    raise HTTPError(http_error_msg, response=self)
requests.exceptions.HTTPError: 404 Client Error: Not Found for url: http+docker://localhost/v1.43/containers/793ae9bd327288627dfd9946ae90a1c1734026c7301a75562423528840f80072/start

The above exception was the direct cause of the following exception:

Traceback (most recent call last):
  File "/home/airflow/.local/lib/python3.7/site-packages/airflow/providers/docker/operators/docker.py", line 430, in execute
    return self._run_image()
  File "/home/airflow/.local/lib/python3.7/site-packages/airflow/providers/docker/operators/docker.py", line 303, in _run_image
    return self._run_image_with_mounts(self.mounts, add_tmp_variable=False)
  File "/home/airflow/.local/lib/python3.7/site-packages/airflow/providers/docker/operators/docker.py", line 348, in _run_image_with_mounts
    self.cli.start(self.container["Id"])
  File "/home/airflow/.local/lib/python3.7/site-packages/docker/utils/decorators.py", line 19, in wrapped
    return f(self, resource_id, *args, **kwargs)
  File "/home/airflow/.local/lib/python3.7/site-packages/docker/api/container.py", line 1126, in start
    self._raise_for_status(res)
  File "/home/airflow/.local/lib/python3.7/site-packages/docker/api/client.py", line 270, in _raise_for_status
    raise create_api_error_from_http_exception(e) from e
  File "/home/airflow/.local/lib/python3.7/site-packages/docker/errors.py", line 39, in create_api_error_from_http_exception
    raise cls(e, response=response, explanation=explanation) from e
docker.errors.NotFound: 404 Client Error for http+docker://localhost/v1.43/containers/793ae9bd327288627dfd9946ae90a1c1734026c7301a75562423528840f80072/start: Not Found ("No such container: dbt")
[2024-05-27T18:26:12.765+0000] {taskinstance.py:1327} INFO - Marking task as FAILED. dag_id=franko_python, task_id=create_seeds, execution_date=20240525T020240, start_date=20240527T182612, end_date=20240527T182612
[2024-05-27T18:26:12.777+0000] {standard_task_runner.py:105} ERROR - Failed to execute job 50 for task create_seeds (404 Client Error for http+docker://localhost/v1.43/containers/793ae9bd327288627dfd9946ae90a1c1734026c7301a75562423528840f80072/start: Not Found ("No such container: dbt"); 1592)
[2024-05-27T18:26:12.800+0000] {local_task_job.py:159} INFO - Task exited with return code 1
[2024-05-27T18:26:12.817+0000] {taskinstance.py:2582} INFO - 0 downstream tasks scheduled from follow-on schedule check
